Workbook

Sheet Title
A2: DETAILED PROJECT REPORT FOR
A3: R R ENTERPRISE
A5: Address : BLOCK NO 203, GOTHAN BRIDGE THI AAGAL UMRA CHOKDI NI BAJUMA,
A6: VELANJA ROAD SURAT, GUJARAT, 395004
A10: PROJECTED FINANCIAL REPORT
A13: BUSINESS ACTIVITY :
A15: MANUFACTURING.
A22: This project has been designed to establish a Manufacturing. It is a Proprietor firm concern owned by BHAVESHKUMAR RAVJIBHAI SOJITRA. The Proprietor hail from business family and is having experience in this line of business.
A23: Now it is proposed to start operation with financial assistance from a suitable commercial bank.
A24: Hence this project Report is presented.

Sheet Sheet1
B5: R R ENTERPRISE
B6: BLOCK NO 203, GOTHAN BRIDGE THI AAGAL UMRA CHOKDI NI BAJUMA
B7: VELANJA ROAD SURAT, GUJARAT, 395004
B14: I N D E X
A17: SL. | B17: C O N T E N T S | C17: PAGES
B18: CHAPTER :
A20: 1 | B20: Project Profile | C20: 1
A21: 2 | B21: Project Fund Requirements | C21: 2
A22: 3 | B22: Production income | C22: 3
A23: 4 | B23: Computation of sales | C23: 4
A24: 5 | B24: Trading Accounts | C24: 5
A25: 6 | B25: Profit And loss Account and Net Profit Rario | C25: 6
A26: 7 | B26: Capital Account and Balance Sheet | C26: 7
A27: 8 | B27: Depreciation Schedule | C27: 8
A28: 9 | B28: Statement Showing DSCR/DE | C28: 11
A29: 10 | B29: Statement Showing Liquidity and Profotability | C29: 12
B30: Ratios.
A31: 11 | B31: Repayment Schedual | C31: 14

Sheet profile
G1: PROFILE
A3: Introduction: | F3: This project proposal outlines the establishment/expansion of a high-efficiency Hotfix Paper (Rhinestone Transfer Tape) Manufacturing and Processing Unit. The unit is designed to produce high-grade acrylic-adhesive silicone transfer paper widely used in the apparel, textile motif, and garment decoration industries. The proposed production setup utilizes a semi-automatic / fully automatic high-speed Hotfix Paper Coating, Slitting, and Rewinding Machine designed for optimal efficiency and minimal waste.
A12: Activity | F12: : MANUFACTURING.
A13: Name of Firm | F13: : R R ENTERPRISE
A14: Name of Proprietery | F14: : BHAVESHKUMAR RAVJIBHAI SOJITRA
A15: PAN | F15: : DNTPS3311D
A16: UDHYAM No. | F16: : UDYAM-GJ-22-0188146
A17: MOBILE No. | F17: : 9662918888
A18: Address | F18: : BLOCK NO 203, GOTHAN BRIDGE THI AAGAL UMRA CHOKDI NI BAJUMA,
F19: VELANJA ROAD SURAT, GUJARAT, 395004
A20: EMAIL ID | F20: : bhaveshsojitra71@gmail.com
A22: -Business Experience | F22: : 12 year
A24: Current Area Of Operation | F24: : Surat
A25: No. Of Manpower | F25: : 5
A27: Infrastructure Facilities
A28: -Space | F28: : 9000+ sq feet
A29: -Connectivity | F29: : Well connected with road
A31: -Location | F31: : Surat
A32: -Electricity & Water | F32: : Yes
A34: Exsisting Facility | F34: : NA
A35: Capital Requirement | F35: : Term Loan: Rs.44.50 lakh
A38: Note
A39: 1. Bank intrest is taken at 09.00%
A40: 2. Assumption are made on going Concern Basis.
A41: 3. This Projected Financial Report includes forecasts, projection and other predictive statements that respresent
A42: firm's assumption and expectations in light of currently available information. These forecasts, etc.,
A43: are based on industry trends, circumstances involving client and other factors, and they involve risks, variables
A44: and uncertainties. The firm's actual performance results may differs, andyhey involve risks, variable and
A45: uncertainties. The firm's actual performance results may differ from those projected n this projected
A46: Financial Report. Consequently, no guarantee is presented or implied as to the accuracy of specific forecast,
A47: projections or predictive atatements contained herein.
L50: page 1

Sheet fund 
A4: R R ENTERPRISE
A5: BLOCK NO 203, GOTHAN BRIDGE THI AAGAL UMRA CHOKDI NI BAJUMA
A6: VELANJA ROAD SURAT, GUJARAT, 395004
A7: FUND REQUIREMENTS
A9: A | B9: ASSETS REQUIREMENT
B10: FIXED ASSET | G10: 5933500
B11: INVENTORY | G11: 0
B12: TOTAL ASSETS | F12: Rs. | G12: =G10+G11 -> 5933500
A14: B | B14: FIXED CAPITAL
B16: MACHINARY | G16: 5933500
B28: Total Fixed Capital Requirements | F28: Rs. | G28: =SUM(G16:G19) -> 5933500
A30: C | B30: WORKING CAPITAL REQUIREMENT
B31: Stock-in-progress | G31: =G11 -> 0
B32: Receivales
B34: Total Working Capital | F34: Rs. | G34: =G31+G32 -> 0
A36: D | B36: TOTAL CAPITAL REQUIREMENT
B37: Fixed Capital | F37: Rs. | G37: =G28 -> 5933500
B38: Working Capital | F38: Rs. | G38: =G34 -> 0
B39: Total Capital Requirement | F39: Rs. | G39: =G37+G38 -> 5933500
A41: E | B41: MEANS OF FINANCE
B42: Promoter's Contri | G42: =G39-G47 -> 1483500
B43: Working Capital | F43: Rs.
B45: Bank's Finance Term Loan | F45: Rs. | G45: 4450000
B46: Working Capital Loan | F46: Rs. | G46: 0
B47: Total Capital Requirement | F47: Rs. | G47: =G45+G46 -> 4450000
A50: FOR R R ENTERPRISE | G50: page 2

Sheet Production
A2: R R ENTERPRISE
A3: BLOCK NO 203, GOTHAN BRIDGE THI AAGAL UMRA CHOKDI NI BAJUMA
A4: VELANJA ROAD SURAT, GUJARAT, 395004
A5: Production Income :
A7: COMPUTATION OF PROVIDING MANUFACTURING of : HOTFIX
A9: MANUFACTURING | E9: HOTFIX
A11: Full Capacity per day | E11: 125000 | F11: PCS
A13: No. of Working Hour | E13: 12 | F13: hour
A15: No of Working Days per month | E15: 26 | F15: day
A17: No. of Working Day per annum | E17: 180 | F17: day
A19: Production Yearly | E19: =E17*E11 -> 22500000 | F19: PCS
A22: Year | C22: Capacity Utilisation | E22: HOTFIX PCS
A23: 2027 | C23: 0.5 | D23: =C19*C23 -> 0 | E23: =E19*C23 -> 11250000
A24: =1+A23 -> 2028 | C24: 0.55 | D24: =ROUND(D23*5%+D23,0) -> 0 | E24: =ROUND(E23*5%+E23,0) -> 11812500
A25: =1+A24 -> 2029 | C25: 0.6 | D25: =ROUND(D24*5%+D24,0) -> 0 | E25: =ROUND(E24*5%+E24,0) -> 12403125
A26: =1+A25 -> 2030 | C26: 0.65 | D26: =ROUND(D25*5%+D25,0) -> 0 | E26: =ROUND(E25*5%+E25,0) -> 13023281
A27: =1+A26 -> 2031 | C27: 0.7 | D27: =ROUND(D26*5%+D26,0) -> 0 | E27: =ROUND(E26*5%+E26,0) -> 13674445
A28: =1+A27 -> 2032 | C28: 0.75 | D28: =ROUND(D27*5%+D27,0) -> 0 | E28: =ROUND(E27*5%+E27,0) -> 14358167
A29: =1+A28 -> 2033 | C29: 0.8 | D29: =ROUND(D28*5%+D28,0) -> 0 | E29: =ROUND(E28*5%+E28,0) -> 15076075
A36: FOR R R ENTERPRISE
E38: page 3

Sheet INCOME
A1: R R ENTERPRISE
A2: BLOCK NO 203, GOTHAN BRIDGE THI AAGAL UMRA CHOKDI NI BAJUMA,
A3: VELANJA ROAD SURAT, GUJARAT, 395004
A7: COMPUTATION OF SALES :
A9: Particulars | B9: 2027 | C9: 2028 | D9: 2029 | E9: 2030 | F9: 2031 | G9: 2032 | H9: 2033
B10: =Production!D23 -> 0 | C10: =Production!D24 -> 0 | D10: =Production!D25 -> 0 | E10: =Production!D26 -> 0 | F10: =Production!D27 -> 0 | G10: =Production!D28 -> 0 | H10: =Production!D29 -> 0
B11: 0 | C11: =B11 -> 0 | D11: =C11 -> 0 | E11: 0 | F11: =E11 -> 0 | G11: 0 | H11: =G11 -> 0
A12: TOTAL | B12: =B10*B11 -> 0 | C12: =C10*C11 -> 0 | D12: =D10*D11 -> 0 | E12: =E10*E11 -> 0 | F12: =F10*F11 -> 0 | G12: =G10*G11 -> 0 | H12: =H10*H11 -> 0
A14: Total Production pcs. | B14: =Production!E23 -> 11250000 | C14: =Production!E24 -> 11812500 | D14: =Production!E25 -> 12403125 | E14: =Production!E26 -> 13023281 | F14: =Production!E27 -> 13674445 | G14: =Production!E28 -> 14358167 | H14: =Production!E29 -> 15076075
A15: Average Rate of per pcs. | B15: 2.2 | C15: =B15 -> 2.2 | D15: =C15 -> 2.2 | E15: 2.3 | F15: =E15 -> 2.3 | G15: 2.5 | H15: =G15 -> 2.5
A16: TOTAL | B16: =B14*B15 -> 24750000 | C16: =C14*C15 -> 25987500 | D16: =D14*D15 -> 27286875 | E16: =E14*E15 -> 29953546 | F16: =F14*F15 -> 31451223 | G16: =G14*G15 -> 35895418 | H16: =H14*H15 -> 37690188
A19: TOTAL Sale (in Lacs) | B19: =B12+B16 -> 24750000 | C19: =C12+C16 -> 25987500 | D19: =D12+D16 -> 27286875 | E19: =ROUND(E12+E16,0) -> 29953546 | F19: =ROUND(F12+F16,0) -> 31451224 | G19: =ROUND(G12+G16,0) -> 35895418 | H19: =ROUND(H12+H16,0) -> 37690188
A28: FOR R R ENTERPRISE
G31: page 4

Sheet trading 
B2: R R ENTERPRISE
B3: BLOCK NO 203, GOTHAN BRIDGE THI AAGAL UMRA CHOKDI NI BAJUMA,
B4: VELANJA ROAD SURAT, GUJARAT, 395004
B5: TRADING ACCOUNT
A7: PARTICULAR | C7: Projected | D7: Projected | E7: Projected | F7: Projected | G7: Projected | H7: Projected | I7: Projected
C8: Year ended | D8: Year ended | E8: Year ended | F8: Year ended | G8: Year ended | H8: Year ended | I8: Year ended
C9: 2027 | D9: =1+C9 -> 2028 | E9: =1+D9 -> 2029 | F9: =1+E9 -> 2030 | G9: =1+F9 -> 2031 | H9: =1+G9 -> 2032 | I9: =1+H9 -> 2033
A10: Gross Receipts
A12: Gross Sales | C12: =INCOME!B19 -> 24750000 | D12: =INCOME!C19 -> 25987500 | E12: =INCOME!D19 -> 27286875 | F12: =INCOME!E19 -> 29953546 | G12: =INCOME!F19 -> 31451224 | H12: =INCOME!G19 -> 35895418 | I12: =INCOME!H19 -> 37690188
B13: Total | C13: =C12 -> 24750000 | D13: =D12 -> 25987500 | E13: =E12 -> 27286875 | F13: =F12 -> 29953546 | G13: =G12 -> 31451224 | H13: =H12 -> 35895418 | I13: =I12 -> 37690188
A15: Consumables
A16: Opening Stock | C16: 0 | D16: =C26 -> 2431200 | E16: =D26 -> 2674320 | F16: =E26 -> 2941752 | G16: =F26 -> 3235927 | H16: =G26 -> 3559520 | I16: =H26 -> 3915472
A18: Perchase account | C18: 22639800 | D18: 21778000 | E18: =ROUND(D18*5%+D18,0) -> 22866900 | F18: 25456900 | G18: =ROUND(F18*5%+F18,0) -> 26729745 | H18: =ROUND(G18*16%+G18,0) -> 31006504 | I18: =ROUND(H18*5%+H18,0) -> 32556829
A19: Raw Material Consumed
A20: Direct Expenses
A21: Electricity Expenses | C21: 42370 | D21: =ROUND(C21*10%+C21,0) -> 46607 | E21: =ROUND(D21*10%+D21,0) -> 51268 | F21: =ROUND(E21*10%+E21,0) -> 56395 | G21: =ROUND(F21*10%+F21,0) -> 62035 | H21: =ROUND(G21*10%+G21,0) -> 68239 | I21: =ROUND(H21*10%+H21,0) -> 75063
A22: Repair & Maintenance | C22: 31290 | D22: =ROUND(C22*10%+C22,0) -> 34419 | E22: =ROUND(D22*10%+D22,0) -> 37861 | F22: =ROUND(E22*10%+E22,0) -> 41647 | G22: =ROUND(F22*10%+F22,0) -> 45812 | H22: =ROUND(G22*10%+G22,0) -> 50393 | I22: =ROUND(H22*10%+H22,0) -> 55432
A23: Labour & Wages | C23: 340000 | D23: =ROUND(C23*10%+C23,0) -> 374000 | E23: =ROUND(D23*10%+D23,0) -> 411400 | F23: =ROUND(E23*10%+E23,0) -> 452540 | G23: =ROUND(F23*10%+F23,0) -> 497794 | H23: =ROUND(G23*10%+G23,0) -> 547573 | I23: =ROUND(H23*10%+H23,0) -> 602330
C24: =C16+C18+C21+C22+C23 -> 23053460 | D24: =D16+D18+D21+D22+D23 -> 24664226 | E24: =E16+E18+E21+E22+E23 -> 26041749 | F24: =F16+F18+F21+F22+F23 -> 28949234 | G24: =G16+G18+G21+G22+G23 -> 30571313 | H24: =H16+H18+H21+H22+H23 -> 35232229 | I24: =I16+I18+I21+I22+I23 -> 37205126
A26: Less: Closing Stock | C26: 2431200 | D26: =ROUND(C26*10%+C26,0) -> 2674320 | E26: =ROUND(D26*10%+D26,0) -> 2941752 | F26: =ROUND(E26*10%+E26,0) -> 3235927 | G26: =ROUND(F26*10%+F26,0) -> 3559520 | H26: =ROUND(G26*10%+G26,0) -> 3915472 | I26: =ROUND(H26*10%+H26,0) -> 4307019
A28: COGS | B28: Total | C28: =C24-C26 -> 20622260 | D28: =D24-D26 -> 21989906 | E28: =E24-E26 -> 23099997 | F28: =F24-F26 -> 25713307 | G28: =G24-G26 -> 27011793 | H28: =H24-H26 -> 31316757 | I28: =I24-I26 -> 32898107
A30: Gross Profit | C30: =C13-C28 -> 4127740 | D30: =D13-D28 -> 3997594 | E30: =E13-E28 -> 4186878 | F30: =F13-F28 -> 4240239 | G30: =G13-G28 -> 4439431 | H30: =H13-H28 -> 4578661 | I30: =I13-I28 -> 4792081
A36: FOR R R ENTERPRISE
G43: page 5

Sheet pnl
A2: R R ENTERPRISE
A3: BLOCK NO 203, GOTHAN BRIDGE THI AAGAL UMRA CHOKDI NI BAJUMA,
A4: VELANJA ROAD SURAT, GUJARAT, 395004
A5: PROFIT & LOSS ACCOUNT
A7: PARTICULAR | C7: Projected | D7: Projected | E7: Projected | F7: Projected | G7: Projected | H7: Projected | I7: Projected
C8: Year ended | D8: Year ended | E8: Year ended | F8: Year ended | G8: Year ended | H8: Year ended | I8: Year ended
C9: 2027 | D9: =1+C9 -> 2028 | E9: =1+D9 -> 2029 | F9: =1+E9 -> 2030 | G9: =1+F9 -> 2031 | H9: =1+G9 -> 2032 | I9: =1+H9 -> 2033
A10: Gross Profit
A11: As Per Trading Account | C11: ='trading '!C30 -> 4127740 | D11: ='trading '!D30 -> 3997594 | E11: ='trading '!E30 -> 4186878 | F11: ='trading '!F30 -> 4240239 | G11: ='trading '!G30 -> 4439431 | H11: ='trading '!H30 -> 4578661 | I11: ='trading '!I30 -> 4792081
A12: Other Income | D12: - | E12: - | F12: - | G12: - | H12: - | I12: -
B13: Total | C13: =C11 -> 4127740 | D13: =D11 -> 3997594 | E13: =E11 -> 4186878 | F13: =F11 -> 4240239 | G13: =G11 -> 4439431 | H13: =H11 -> 4578661 | I13: =I11 -> 4792081
A15: Cost of Goods
A16: Indirect Expenses
A17: To Accounting/audit Charges | C17: 30000 | D17: =ROUND(C17*10%+C17,0) -> 33000 | E17: =ROUND(D17*10%+D17,0) -> 36300 | F17: =ROUND(E17*10%+E17,0) -> 39930 | G17: =ROUND(F17*10%+F17,0) -> 43923 | H17: =ROUND(G17*10%+G17,0) -> 48315 | I17: =ROUND(H17*10%+H17,0) -> 53147
A18: To bank Charges | C18: 3890 | D18: =ROUND(C18*10%+C18,0) -> 4279 | E18: =ROUND(D18*10%+D18,0) -> 4707 | F18: =ROUND(E18*10%+E18,0) -> 5178 | G18: =ROUND(F18*10%+F18,0) -> 5696 | H18: =ROUND(G18*10%+G18,0) -> 6266 | I18: =ROUND(H18*10%+H18,0) -> 6893
A19: To Transport Exp. | C19: 141230 | D19: =ROUND(C19*10%+C19,0) -> 155353 | E19: =ROUND(D19*10%+D19,0) -> 170888 | F19: =ROUND(E19*10%+E19,0) -> 187977 | G19: =ROUND(F19*10%+F19,0) -> 206775 | H19: =ROUND(G19*10%+G19,0) -> 227453 | I19: =ROUND(H19*10%+H19,0) -> 250198
A20: To Interest Paid to Bank | C20: ='repayment '!D10 -> 400500 | D20: ='repayment '!D11 -> 375777 | E20: ='repayment '!D12 -> 316443 | F20: ='repayment '!D13 -> 257109 | G20: ='repayment '!D14 -> 197775 | H20: ='repayment '!D15 -> 138441 | I20: ='repayment '!D16 -> 79107
A21: To Interest Paid to Bank CC | C21: ='repayment '!F23 -> 0 | D21: =C21 -> 0 | E21: =D21 -> 0 | F21: =E21 -> 0 | G21: =F21 -> 0 | H21: =G21 -> 0 | I21: =H21 -> 0
A22: To Stationery | C22: 2130 | D22: =ROUND(C22*10%+C22,0) -> 2343 | E22: =ROUND(D22*10%+D22,0) -> 2577 | F22: =ROUND(E22*10%+E22,0) -> 2835 | G22: =ROUND(F22*10%+F22,0) -> 3119 | H22: =ROUND(G22*10%+G22,0) -> 3431 | I22: =ROUND(H22*10%+H22,0) -> 3774
A23: To Other Exp | C23: 78670 | D23: =ROUND(C23*10%+C23,0) -> 86537 | E23: =ROUND(D23*10%+D23,0) -> 95191 | F23: =ROUND(E23*30%+E23,0) -> 123748 | G23: =ROUND(F23*10%+F23,0) -> 136123 | H23: =ROUND(G23*10%+G23,0) -> 149735 | I23: =ROUND(H23*10%+H23,0) -> 164709
A24: To Telephone & Mobile Exp | C24: 4800 | D24: =ROUND(C24*10%+C24,0) -> 5280 | E24: =ROUND(D24*10%+D24,0) -> 5808 | F24: =ROUND(E24*10%+E24,0) -> 6389 | G24: =ROUND(F24*10%+F24,0) -> 7028 | H24: =ROUND(G24*10%+G24,0) -> 7731 | I24: =ROUND(H24*10%+H24,0) -> 8504
A25: To Depreciation | C25: =bs!C26 -> 1054661 | D25: =bs!D26 -> 896461 | E25: =bs!E26 -> 761992 | F25: =bs!F26 -> 647693 | G25: =bs!G26 -> 550539 | H25: =bs!H26 -> 467958 | I25: =bs!I26 -> 397765
A26: To Rent Exp. | C26: 900000 | D26: =C26 -> 900000 | E26: =D26 -> 900000 | F26: =ROUND(E26*10%+E26,0) -> 990000 | G26: =F26 -> 990000 | H26: =G26 -> 990000 | I26: =ROUND(H26*10%+H26,0) -> 1089000
A27: To Salary Exp. | C27: 740000 | D27: =ROUND(C27*10%+C27,0) -> 814000 | E27: =ROUND(D27*10%+D27,0) -> 895400 | F27: =ROUND(E27*10%+E27,0) -> 984940 | G27: =ROUND(F27*10%+F27,0) -> 1083434 | H27: =ROUND(G27*10%+G27,0) -> 1191777 | I27: =ROUND(H27*10%+H27,0) -> 1310955
B28: Total | C28: =SUM(C17:C27) -> 3355881 | D28: =SUM(D17:D27) -> 3273030 | E28: =SUM(E17:E27) -> 3189306 | F28: =SUM(F17:F27) -> 3245799 | G28: =SUM(G17:G27) -> 3224412 | H28: =SUM(H17:H27) -> 3231107 | I28: =SUM(I17:I27) -> 3364052
A30: Net Profit Befor Tax | C30: =C13-C28 -> 771859 | D30: =D13-D28 -> 724564 | E30: =E13-E28 -> 997572 | F30: =F13-F28 -> 994440 | G30: =G13-G28 -> 1215019 | H30: =H13-H28 -> 1347554 | I30: =I13-I28 -> 1428029
A31: Provision for Tax | C31: 0 | D31: 0 | E31: 0 | H31: =20000+40000+20100 -> 80100 | I31: =20000+40000+34200 -> 94200
A32: Net Profit After Tax | C32: =C30-C31 -> 771859 | D32: =D30-D31 -> 724564 | E32: =E30-E31 -> 997572 | F32: =F30-F31 -> 994440 | G32: =G30-G31 -> 1215019 | H32: =H30-H31 -> 1267454 | I32: =I30-I31 -> 1333829
A34: Net Profit Ratio | C34: =Ratio!C39 -> 0.031186222 | D34: =Ratio!D39 -> 0.027881251 | E34: =Ratio!E39 -> 0.036558675 | F34: =Ratio!F39 -> 0.033199408 | G34: =Ratio!G39 -> 0.038631851 | H34: =Ratio!H39 -> 0.035309632 | I34: =Ratio!I39 -> 0.03538929
A40: FOR R R ENTERPRISE
H50: page 6

Sheet bs
A2: R R ENTERPRISE
A3: BLOCK NO 203, GOTHAN BRIDGE THI AAGAL UMRA CHOKDI NI BAJUMA,
A4: VELANJA ROAD SURAT, GUJARAT, 395004
A5: BALANCE SHEET
A7: PARTICULAR | C7: Projected | D7: Projected | E7: Projected | F7: Projected | G7: Projected | H7: Projected | I7: Projected
C8: Year ended | D8: Year ended | E8: Year ended | F8: Year ended | G8: Year ended | H8: Year ended | I8: Year ended
C9: 2027 | D9: =1+C9 -> 2028 | E9: =1+D9 -> 2029 | F9: =1+E9 -> 2030 | G9: =1+F9 -> 2031 | H9: =1+G9 -> 2032 | I9: =1+H9 -> 2033
A10: Capital Account
A11: Opening Capital | C11: 4877560 | D11: =C14 -> 5223819 | E11: =D14 -> 5480223 | F11: =E14 -> 5962819 | G11: =F14 -> 6390785 | H11: =G14 -> 6982683 | I11: =H14 -> 7564704
A12: Add: New Profit after Tax | C12: =pnl!C32 -> 771859 | D12: =pnl!D32 -> 724564 | E12: =pnl!E32 -> 997572 | F12: =pnl!F32 -> 994440 | G12: =pnl!G32 -> 1215019 | H12: =pnl!H32 -> 1267454 | I12: =pnl!I32 -> 1333829
A13: Less: Drawing | C13: 425600 | D13: =ROUND(C13*10%+C13,0) -> 468160 | E13: =ROUND(D13*10%+D13,0) -> 514976 | F13: =ROUND(E13*10%+E13,0) -> 566474 | G13: =ROUND(F13*10%+F13,0) -> 623121 | H13: =ROUND(G13*10%+G13,0) -> 685433 | I13: =ROUND(H13*10%+H13,0) -> 753976
C14: =C11+C12-C13 -> 5223819 | D14: =D11+D12-D13 -> 5480223 | E14: =E11+E12-E13 -> 5962819 | F14: =F11+F12-F13 -> 6390785 | G14: =G11+G12-G13 -> 6982683 | H14: =H11+H12-H13 -> 7564704 | I14: =I11+I12-I13 -> 8144557
A15: Loan Fund
A17: Term Loan | C17: ='repayment '!F10 -> 4175305 | D17: ='repayment '!F11 -> 3516037 | E17: ='repayment '!F12 -> 2856769 | F17: ='repayment '!F13 -> 2197501 | G17: ='repayment '!F14 -> 1538233 | H17: ='repayment '!F15 -> 878965 | I17: ='repayment '!F16 -> 219697
A18: CC | C18: 0 | D18: 0 | E18: =D18 -> 0 | F18: =E18 -> 0 | G18: =F18 -> 0 | H18: =G18 -> 0 | I18: =H18 -> 0
A20: Current Liabilities
A21: Sundry Creditors | C21: 1312400 | D21: =ROUND(C21*10%+C21,0) -> 1443640 | E21: =ROUND(D21*10%+D21,0) -> 1588004 | F21: =ROUND(E21*30%+E21,0) -> 2064405 | G21: =ROUND(F21*20%+F21,0) -> 2477286 | H21: =ROUND(G21*20%+G21,0) -> 2972743 | I21: =ROUND(H21*30%+H21,0) -> 3864566
B22: Total | C22: =C17+C21+C14+C18+C20 -> 10711524 | D22: =D17+D21+D14+D18+D20 -> 10439900 | E22: =E14+E17+E21+E18+E20 -> 10407592 | F22: =F14+F17+F21+F18+F20 -> 10652691 | G22: =G14+G17+G21+G18+G20 -> 10998202 | H22: =H14+H17+H21+H18+H20 -> 11416412 | I22: =I14+I17+I21+I18+I20 -> 12228820
A24: Fixed Assets
A25: Fixed Assets | C25: =FA!F12 -> 7031070 | D25: =FA!F21 -> 5976410 | E25: =FA!F30 -> 5079948 | F25: =FA!F44 -> 4317956 | G25: =FA!F54 -> 3670262 | H25: =FA!F76 -> 3119723 | I25: =FA!F86 -> 2651765
A26: Less: Dep | C26: =FA!G12 -> 1054661 | D26: =FA!G21 -> 896461 | E26: =FA!G30 -> 761992 | F26: =FA!G44 -> 647693 | G26: =FA!G54 -> 550539 | H26: =FA!G76 -> 467958 | I26: =FA!G86 -> 397765
C27: =C25-C26 -> 5976409 | D27: =D25-D26 -> 5079949 | E27: =E25-E26 -> 4317956 | F27: =F25-F26 -> 3670263 | G27: =G25-G26 -> 3119723 | H27: =H25-H26 -> 2651765 | I27: =I25-I26 -> 2254000
A29: Investment
A30: Other Investment | C30: 250000 | D30: =ROUND(C30*20%+C30,0) -> 300000 | E30: =ROUND(D30*20%+D30,0) -> 360000 | F30: 680401 | G30: 858062 | H30: 1075413 | I30: 1075000
A32: Current Assets
A33: Inventory | C33: ='trading '!C26 -> 2431200 | D33: ='trading '!D26 -> 2674320 | E33: ='trading '!E26 -> 2941752 | F33: ='trading '!F26 -> 3235927 | G33: ='trading '!G26 -> 3559520 | H33: ='trading '!H26 -> 3915472 | I33: ='trading '!I26 -> 4307019
A34: Sundry Debtor | C34: 1432100 | D34: =ROUND(C34*10%+C34,0) -> 1575310 | E34: =ROUND(D34*10%+D34,0) -> 1732841 | F34: =ROUND(E34*10%+E34,0) -> 1906125 | G34: =ROUND(F34*10%+F34,0) -> 2096738 | H34: =ROUND(G34*10%+G34,0) -> 2306412 | I34: =ROUND(H34*10%+H34,0) -> 2537053
A35: Other Assetes | C35: 360000 | D35: =ROUND(C35*10%+C35,0) -> 396000 | E35: =ROUND(D35*10%+D35,0) -> 435600 | F35: =ROUND(E35*10%+E35,0) -> 479160 | G35: =ROUND(F35*10%+F35,0) -> 527076 | H35: =ROUND(G35*10%+G35,0) -> 579784 | I35: =ROUND(H35*10%+H35,0) -> 637762
A36: Cash & Bank Balance | C36: 261815 | D36: 414321 | E36: 619443 | F36: 680815 | G36: 837083 | H36: 887566 | I36: 1417986
B38: Total | C38: =C27+C33+C34+C35+C36+C30 -> 10711524 | D38: =D27+D33+D34+D35+D36+D30 -> 10439900 | E38: =E27+E33+E34+E35+E36+E30 -> 10407592 | F38: =F27+F33+F34+F35+F36+F30 -> 10652691 | G38: =G27+G33+G34+G35+G36+G30 -> 10998202 | H38: =H27+H33+H34+H35+H36+H30 -> 11416412 | I38: =I27+I33+I34+I35+I36+I30 -> 12228820
C39: =C38-C22 -> 0 | D39: =D38-D22 -> 0 | E39: =E38-E22 -> 0 | F39: =F38-F22 -> 0 | G39: =G38-G22 -> 0 | H39: =H38-H22 -> 0 | I39: =I38-I22 -> 0
A40: FOR R R ENTERPRISE
G46: page 7

Sheet FA
A2: R R ENTERPRISE | I2: page 8
A3: BLOCK NO 203, GOTHAN BRIDGE THI AAGAL UMRA CHOKDI NI BAJUMA,
A4: VELANJA ROAD SURAT, GUJARAT, 395004
A6: SCHEDULE OF FIXED ASSETS AS ON 31.03.2027
C7: WDV As on | D7: Additional During | E7: Sales/ | F7: Total | H7: WDV As on
A8: Assets | B8: Rate | C8: 01.04.2026 | D8: the Year | E8: Deletion | F8: Amount | G8: Depreciation | H8: 31.3.2027
A9: Bike and Vehicle | B9: 15 | D9: 996495 | E9: - | F9: =D9 -> 996495 | G9: =F9*15/100 -> 149474.25 | H9: =F9-G9 -> 847020.75
A10: MACHINARY | B10: 15 | D10: 5933500 | E10: - | F10: =D10 -> 5933500 | G10: =F10*15/100 -> 890025 | H10: =F10-G10 -> 5043475
A11: Mobile/Computer/TV | B11: 15 | D11: 101075 | E11: - | F11: =D11 -> 101075 | G11: =F11*15/100 -> 15161.25 | H11: =F11-G11 -> 85913.75
A12: Toatal | D12: =D9+D10+D11 -> 7031070 | E12: - | F12: =F9+F10+F11 -> 7031070 | G12: =ROUND(G9+G10+G11,0) -> 1054661 | H12: =ROUND(H9+H10+H11,0) -> 5976410
A14: SCHEDULE OF FIXED ASSETS AS ON 31.03.2028
C16: WDV As on | D16: Additional During | E16: Sales/ | F16: Total | H16: WDV As on
A17: Assets | B17: Rate | C17: 01.04.2027 | D17: the Year | E17: Deletion | F17: Amount | G17: Depreciation | H17: 31.3.2028
A18: Bike and Vehicle | B18: 15 | C18: =H9 -> 847020.75 | D18: 0 | E18: 0 | F18: =C18+D18-E18 -> 847020.75 | G18: =F18*15/100 -> 127053.11 | H18: =F18-G18 -> 719967.64
A19: MACHINARY | B19: 15 | C19: =H10 -> 5043475 | D19: 0 | E19: 0 | F19: =C19+D19-E19 -> 5043475 | G19: =F19*15/100 -> 756521.25 | H19: =F19-G19 -> 4286953.8
A20: Mobile/Computer/TV | B20: 15 | C20: =H11 -> 85913.75 | D20: 0 | E20: 0 | F20: =C20+D20-E20 -> 85913.75 | G20: =F20*15/100 -> 12887.062 | H20: =F20-G20 -> 73026.688
A21: Toatal | C21: =H12 -> 5976410 | D21: =D18+D19+D20 -> 0 | E21: 0 | F21: =C21+D21 -> 5976410 | G21: =ROUND(G18+G19+G20,0) -> 896461 | H21: =ROUND(H18+H19+H20,0) -> 5079948
A23: SCHEDULE OF FIXED ASSETS AS ON 31.03.2029
C25: WDV As on | D25: Additional During | E25: Sales/ | F25: Total | H25: WDV As on
A26: Assets | B26: Rate | C26: 01.04.2028 | D26: the Year | E26: Deletion | F26: Amount | G26: Depreciation | H26: 31.3.2029
A27: Bike and Vehicle | B27: 15 | C27: =H18 -> 719967.64 | D27: 0 | E27: 0 | F27: =C27+D27-E27 -> 719967.64 | G27: =F27*15/100 -> 107995.15 | H27: =F27-G27 -> 611972.49
A28: MACHINARY | B28: 15 | C28: =H19 -> 4286953.8 | D28: 0 | E28: 0 | F28: =C28+D28-E28 -> 4286953.8 | G28: =F28*15/100 -> 643043.06 | H28: =F28-G28 -> 3643910.7
A29: Mobile/Computer/TV | B29: 15 | C29: =H20 -> 73026.688 | D29: 0 | E29: 0 | F29: =C29+D29-E29 -> 73026.688 | G29: =F29*15/100 -> 10954.003 | H29: =F29-G29 -> 62072.684
A30: Toatal | C30: =H21 -> 5079948 | D30: 0 | E30: 0 | F30: =C30 -> 5079948 | G30: =ROUND(G27+G28+G29,0) -> 761992 | H30: =ROUND(H27+H28+H29,0) -> 4317956
A32: R R ENTERPRISE
A34: 173/A-2, 5TH FLOOR, SOUTH BABRIK INDUSTRIAL,
A35: VELANJA ROAD SURAT, GUJARAT, 395004
A37: SCHEDULE OF FIXED ASSETS AS ON 31.03.2030
C39: WDV As on | D39: Additional During | E39: Sales/ | F39: Total | H39: WDV As on
A40: Assets | B40: Rate | C40: 01.04.2029 | D40: the Year | E40: Deletion | F40: Amount | G40: Depreciation | H40: 31.3.2030
A41: Bike and Vehicle | B41: 15 | C41: =H27 -> 611972.49 | D41: 0 | E41: 0 | F41: =C41+D41-E41 -> 611972.49 | G41: =F41*15/100 -> 91795.874 | H41: =F41-G41 -> 520176.62
A42: MACHINARY | B42: 15 | C42: =H28 -> 3643910.7 | D42: 0 | E42: 0 | F42: =C42+D42-E42 -> 3643910.7 | G42: =F42*15/100 -> 546586.6 | H42: =F42-G42 -> 3097324.1
A43: Mobile/Computer/TV | B43: 15 | C43: =H29 -> 62072.684 | D43: 0 | E43: 0 | F43: =C43+D43-E43 -> 62072.684 | G43: =F43*15/100 -> 9310.9027 | H43: =F43-G43 -> 52761.782
A44: Toatal | C44: =H30 -> 4317956 | D44: 0 | E44: 0 | F44: =C44 -> 4317956 | G44: =ROUND(G41+G42+G43,0) -> 647693 | H44: =ROUND(H41+H42+H43,0) -> 3670262
A47: SCHEDULE OF FIXED ASSETS AS ON 31.03.2031
C49: WDV As on | D49: Additional During | E49: Sales/ | F49: Total | H49: WDV As on
A50: Assets | B50: Rate | C50: 01.04.2030 | D50: the Year | E50: Deletion | F50: Amount | G50: Depreciation | H50: 31.3.2031
A51: Bike and Vehicle | B51: 15 | C51: =H41 -> 520176.62 | D51: 0 | E51: 0 | F51: =C51+D51-E51 -> 520176.62 | G51: =F51*15/100 -> 78026.493 | H51: =F51-G51 -> 442150.13
A52: MACHINARY | B52: 15 | C52: =H42 -> 3097324.1 | D52: 0 | E52: 0 | F52: =C52+D52-E52 -> 3097324.1 | G52: =F52*15/100 -> 464598.61 | H52: =F52-G52 -> 2632725.5
A53: Mobile/Computer/TV | B53: 15 | C53: =H43 -> 52761.782 | D53: 0 | E53: 0 | F53: =C53+D53-E53 -> 52761.782 | G53: =F53*15/100 -> 7914.2673 | H53: =F53-G53 -> 44847.514
...

Sheet DSCR
A2: R R ENTERPRISE
A3: BLOCK NO 203, GOTHAN BRIDGE THI AAGAL UMRA CHOKDI NI BAJUMA,
A4: VELANJA ROAD SURAT, GUJARAT, 395004
A5: STATEMENT SHOWING DSCR
A7: PARTICULAR | C7: Projected | D7: Projected | E7: Projected | F7: Projected | G7: Projected | H7: Projected | I7: Projected
C8: Year ended | D8: Year ended | E8: Year ended | F8: Year ended | G8: Year ended | H8: Year ended | I8: Year ended
C9: 2027 | D9: =1+C9 -> 2028 | E9: =1+D9 -> 2029 | F9: =1+E9 -> 2030 | G9: =1+F9 -> 2031 | H9: =1+G9 -> 2032 | I9: =1+H9 -> 2033
A10: Net Profit | C10: =pnl!C32 -> 771859 | D10: =pnl!D32 -> 724564 | E10: =pnl!E32 -> 997572 | F10: =pnl!F32 -> 994440 | G10: =pnl!G32 -> 1215019 | H10: =pnl!H32 -> 1267454 | I10: =pnl!I32 -> 1333829
A11: Depreciation | C11: =bs!C26 -> 1054661 | D11: =bs!D26 -> 896461 | E11: =bs!E26 -> 761992 | F11: =bs!F26 -> 647693 | G11: =bs!G26 -> 550539 | H11: =bs!H26 -> 467958 | I11: =bs!I26 -> 397765
A12: Interest on Bank Loan | C12: =pnl!C20 -> 400500 | D12: =pnl!D20 -> 375777 | E12: =pnl!E20 -> 316443 | F12: =pnl!F20 -> 257109 | G12: =pnl!G20 -> 197775 | H12: =pnl!H20 -> 138441 | I12: =pnl!I20 -> 79107
A14: Total Amount | C14: =C10+C11+C12 -> 2227020 | D14: =D10+D11+D12 -> 1996802 | E14: =E10+E11+E12 -> 2076007 | F14: =F10+F11+F12 -> 1899242 | G14: =G10+G11+G12 -> 1963333 | H14: =H10+H11+H12 -> 1873853 | I14: =I10+I11+I12 -> 1810701
A16: Interest on Bank Loan | C16: =C12 -> 400500 | D16: =D12 -> 375777 | E16: =E12 -> 316443 | F16: =F12 -> 257109 | G16: =G12 -> 197775 | H16: =H12 -> 138441 | I16: =I12 -> 79107
A17: Repayment of Loan | C17: ='repayment '!C10 -> 274695 | D17: ='repayment '!C11 -> 659268 | E17: ='repayment '!C12 -> 659268 | F17: ='repayment '!C13 -> 659268 | G17: ='repayment '!C14 -> 659268 | H17: ='repayment '!C15 -> 659268 | I17: ='repayment '!C16 -> 659268
A19: Total Amount | C19: =C16+C17 -> 675195 | D19: =D16+D17 -> 1035045 | E19: =E16+E17 -> 975711 | F19: =F16+F17 -> 916377 | G19: =G16+G17 -> 857043 | H19: =H16+H17 -> 797709 | I19: =I16+I17 -> 738375
A21: DSCR | C21: 3.29 | D21: 1.92 | E21: 2.12 | F21: 2.07 | G21: 2.29 | H21: 2.34 | I21: 2.45
A23: Average DSCR | D23: 2.35
C24: =C14/C19 -> 3.298336 | D24: =D14/D19 -> 1.9291934 | E24: =E14/E19 -> 2.1276864 | F24: =F14/F19 -> 2.0725553 | G24: =G14/G19 -> 2.290822 | H24: =H14/H19 -> 2.3490433 | I24: =I14/I19 -> 2.4522783
A26: STATEMENT SHOWING D/E Ratio
A28: PARTICULAR | C28: Projected | D28: Projected | E28: Projected | F28: Projected | G28: Projected | H28: Projected | I28: Projected
C29: Year ended | D29: Year ended | E29: Year ended | F29: Year ended | G29: Year ended | H29: Year ended | I29: Year ended
C30: 2027 | D30: =1+C30 -> 2028 | E30: =1+D30 -> 2029 | F30: =1+E30 -> 2030 | G30: =1+F30 -> 2031 | H30: =1+G30 -> 2032 | I30: =1+H30 -> 2033
A32: TOTAL LIABILITIES | C32: =bs!C17+bs!C21 -> 5487705 | D32: =bs!D17+bs!D21 -> 4959677 | E32: =bs!E17+bs!E21 -> 4444773 | F32: =bs!F17+bs!F21 -> 4261906 | G32: =bs!G17+bs!G21 -> 4015519 | H32: =bs!H17+bs!H21 -> 3851708 | I32: =bs!I17+bs!I21 -> 4084263
A34: EQUITY | C34: =bs!C11 -> 4877560 | D34: =bs!D11 -> 5223819 | E34: =bs!E11 -> 5480223 | F34: =bs!F11 -> 5962819 | G34: =bs!G11 -> 6390785 | H34: =bs!H11 -> 6982683 | I34: =bs!I11 -> 7564704
A36: DEBT to EQUITY RATIO | C36: 1.12 | D36: 0.94 | E36: 0.81 | F36: 0.71 | G36: 0.62 | H36: 0.55 | I36: 0.53
C37: =C32/C34 -> 1.1250923 | D37: =D32/D34 -> 0.94943508 | E37: =E32/E34 -> 0.81105696 | F37: =F32/F34 -> 0.71474683 | G37: =G32/G34 -> 0.62832954 | H37: =H32/H34 -> 0.5516086 | I37: =I32/I34 -> 0.53991048
A40: FOR R R ENTERPRISE
G42: page 11

Sheet Ratio
A2: R R ENTERPRISE
A3: BLOCK NO 203, GOTHAN BRIDGE THI AAGAL UMRA CHOKDI NI BAJUMA,
A4: VELANJA ROAD SURAT, GUJARAT, 395004
A6: STATEMENT SHOWING LIQUIDITY AND PROFITABILITY RATIOS
A8: PARTICULAR | C8: Projected | D8: Projected | E8: Projected | F8: Projected | G8: Projected | H8: Projected | I8: Projected
C9: Year ended | D9: Year ended | E9: Year ended | F9: Year ended | G9: Year ended | H9: Year ended | I9: Year ended
C10: 2027 | D10: =1+C10 -> 2028 | E10: =1+D10 -> 2029 | F10: =1+E10 -> 2030 | G10: =1+F10 -> 2031 | H10: =1+G10 -> 2032 | I10: =1+H10 -> 2033
A11: NET WORTH
A12: TOTAL ASSETS
A13: fixed Assets | C13: =bs!C25 -> 7031070 | D13: =bs!D25 -> 5976410 | E13: =bs!E25 -> 5079948 | F13: =bs!F25 -> 4317956 | G13: =bs!G25 -> 3670262 | H13: =bs!H25 -> 3119723 | I13: =bs!I25 -> 2651765
A14: Investment & Advances | C14: =bs!C30 -> 250000 | D14: =bs!D30 -> 300000 | E14: =bs!E30 -> 360000 | F14: =bs!F30 -> 680401 | G14: =bs!G30 -> 858062 | H14: =bs!H30 -> 1075413 | I14: =bs!I30 -> 1075000
A15: Current Assetes | C15: =bs!C38-bs!C30-bs!C27 -> 4485115 | D15: =bs!D38-bs!D30-bs!D27 -> 5059951 | E15: =bs!E38-bs!E30-bs!E27 -> 5729636 | F15: =bs!F38-bs!F30-bs!F27 -> 6302027 | G15: =bs!G38-bs!G30-bs!G27 -> 7020417 | H15: =bs!H38-bs!H30-bs!H27 -> 7689234 | I15: =bs!I38-bs!I30-bs!I27 -> 8899820
C16: =C13+C14+C15 -> 11766185 | D16: =D13+D14+D15 -> 11336361 | E16: =E13+E14+E15 -> 11169584 | F16: =F13+F14+F15 -> 11300384 | G16: =G13+G14+G15 -> 11548741 | H16: =H13+H14+H15 -> 11884370 | I16: =I13+I14+I15 -> 12626585
A17: TOTAL LIABILITIES
A18: sundry Creditor | C18: =bs!C21 -> 1312400 | D18: =bs!D21 -> 1443640 | E18: =bs!E21 -> 1588004 | F18: =bs!F21 -> 2064405 | G18: =bs!G21 -> 2477286 | H18: =bs!H21 -> 2972743 | I18: =bs!I21 -> 3864566
A19: Loan From Bank & Other | C19: =bs!C17+bs!C18 -> 4175305 | D19: =bs!D17+bs!D18 -> 3516037 | E19: =bs!E17+bs!E18 -> 2856769 | F19: =bs!F17+bs!F18 -> 2197501 | G19: =bs!G17+bs!G18 -> 1538233 | H19: =bs!H17+bs!H18 -> 878965 | I19: =bs!I17+bs!I18 -> 219697
A20: Other Liabilities | C20: - | D20: - | E20: - | F20: - | G20: - | H20: - | I20: -
C21: =C19+C18 -> 5487705 | D21: =D19+D18 -> 4959677 | E21: =E18+E19 -> 4444773 | F21: =F18+F19 -> 4261906 | G21: =G18+G19 -> 4015519 | H21: =H18+H19 -> 3851708 | I21: =I18+I19 -> 4084263
A23: NET WORTH | C23: =C16-C21 -> 6278480 | D23: =D16-D21 -> 6376684 | E23: =E16-E21 -> 6724811 | F23: =F16-F21 -> 7038478 | G23: =G16-G21 -> 7533222 | H23: =H16-H21 -> 8032662 | I23: =I16-I21 -> 8542322
A25: Gross Profit
A26: Turnover | C26: ='trading '!C12 -> 24750000 | D26: ='trading '!D12 -> 25987500 | E26: ='trading '!E12 -> 27286875 | F26: ='trading '!F12 -> 29953546 | G26: ='trading '!G12 -> 31451224 | H26: ='trading '!H12 -> 35895418 | I26: ='trading '!I12 -> 37690188
A27: Cost Of Good Sold
A28: Opening Stock | C28: ='trading '!C16 -> 0 | D28: ='trading '!D16 -> 2431200 | E28: ='trading '!E16 -> 2674320 | F28: ='trading '!F16 -> 2941752 | G28: ='trading '!G16 -> 3235927 | H28: ='trading '!H16 -> 3559520 | I28: ='trading '!I16 -> 3915472
A29: Purchase & Direct Expenses | C29: ='trading '!C24 -> 23053460 | D29: ='trading '!D24 -> 24664226 | E29: ='trading '!E24 -> 26041749 | F29: ='trading '!F24 -> 28949234 | G29: ='trading '!G24 -> 30571313 | H29: ='trading '!H24 -> 35232229 | I29: ='trading '!I24 -> 37205126
A30: Less Closing Stock | C30: =-('trading '!C26) -> -2431200 | D30: =-('trading '!D26) -> -2674320 | E30: =-('trading '!E26) -> -2941752 | F30: =-('trading '!F26) -> -3235927 | G30: =-('trading '!G26) -> -3559520 | H30: =-('trading '!H26) -> -3915472 | I30: =-('trading '!I26) -> -4307019
A31: Cost Of Good Sold | C31: =C29+C30 -> 20622260 | D31: =D29+D30 -> 21989906 | E31: =E29+E30 -> 23099997 | F31: =F29+F30 -> 25713307 | G31: =G29+G30 -> 27011793 | H31: =H29+H30 -> 31316757 | I31: =I29+I30 -> 32898107
A33: Gross Profit | C33: =C26-C31 -> 4127740 | D33: =D26-D31 -> 3997594 | E33: =E26-E31 -> 4186878 | F33: =F26-F31 -> 4240239 | G33: =G26-G31 -> 4439431 | H33: =H26-H31 -> 4578661 | I33: =I26-I31 -> 4792081
A34: Gross Profit Ratio | C34: =C33/C26 -> 0.16677737 | D34: =D33/D26 -> 0.15382757 | E34: =E33/E26 -> 0.15343926 | F34: =F33/F26 -> 0.1415605 | G34: =G33/G26 -> 0.14115288 | H34: =H33/H26 -> 0.12755558 | I34: =I33/I26 -> 0.12714399
A36: NET PROFT RATIO
A37: Net Profit | C37: =pnl!C32 -> 771859 | D37: =pnl!D32 -> 724564 | E37: =pnl!E32 -> 997572 | F37: =pnl!F32 -> 994440 | G37: =pnl!G32 -> 1215019 | H37: =pnl!H32 -> 1267454 | I37: =pnl!I32 -> 1333829
A38: Sales | C38: ='trading '!C12 -> 24750000 | D38: ='trading '!D12 -> 25987500 | E38: ='trading '!E12 -> 27286875 | F38: ='trading '!F12 -> 29953546 | G38: ='trading '!G12 -> 31451224 | H38: ='trading '!H12 -> 35895418 | I38: ='trading '!I12 -> 37690188
A39: Net Profit Ratio | C39: =C37/C38 -> 0.031186222 | D39: =D37/D38 -> 0.027881251 | E39: =E37/E38 -> 0.036558675 | F39: =F37/F38 -> 0.033199408 | G39: =G37/G38 -> 0.038631851 | H39: =H37/H38 -> 0.035309632 | I39: =I37/I38 -> 0.03538929
A41: PROJECTED TREND OF SALES
A42: Sales | C42: =C38 -> 24750000 | D42: =D38 -> 25987500 | E42: =E38 -> 27286875 | F42: =F38 -> 29953546 | G42: =G38 -> 31451224 | H42: =H38 -> 35895418 | I42: =I38 -> 37690188
A43: Increase Of Sale | D43: =D42-C42 -> 1237500 | E43: =E42-D42 -> 1299375 | F43: =F42-E42 -> 2666671 | G43: =G42-F42 -> 1497678 | H43: =H42-G42 -> 4444194 | I43: =I42-H42 -> 1794770
A44: % Of Increase Sales | D44: 0.2 | E44: 0.2 | F44: 0.2 | G44: 0.2 | H44: 0.2 | I44: 0.2
H47: page 12
A60: INVENTORY HOLDING OF SALES
A61: Closing Stock | C61: ='trading '!C26 -> 2431200 | D61: ='trading '!D26 -> 2674320 | E61: ='trading '!E26 -> 2941752 | F61: ='trading '!F26 -> 3235927 | G61: ='trading '!G26 -> 3559520 | H61: ='trading '!H26 -> 3915472 | I61: ='trading '!I26 -> 4307019
A62: Cost Of Good Sold | C62: ='trading '!C28 -> 20622260 | D62: ='trading '!D28 -> 21989906 | E62: ='trading '!E28 -> 23099997 | F62: ='trading '!F28 -> 25713307 | G62: ='trading '!G28 -> 27011793 | H62: ='trading '!H28 -> 31316757 | I62: ='trading '!I28 -> 32898107
...

Sheet repayment 
A2: R R ENTERPRISE
A3: BLOCK NO 203, GOTHAN BRIDGE THI AAGAL UMRA CHOKDI NI BAJUMA,
A4: VELANJA ROAD SURAT, GUJARAT, 395004
A6: Repayment Schedule of Term Loan
A8: Year | B8: EMI | C8: Principal | D8: Interest | E8: Total Interest | F8: O/s principal | G8: Month | H8: ROI
E9: Paid | F9: 4450000 | H9: 0.09
A10: 31.03.2027 | B10: 54939 | C10: =+B10*5 -> 274695 | D10: =ROUND(+F9*H10,0) -> 400500 | E10: =D10 -> 400500 | F10: =ROUND(+F9-C10,0) -> 4175305 | G10: 5 | H10: 0.09
A11: 31.03.2028 | B11: =B10 -> 54939 | C11: =+B11*12 -> 659268 | D11: =ROUND(+F10*H11,0) -> 375777 | E11: =E10+D11 -> 776277 | F11: =ROUND(+F10-C11,0) -> 3516037 | G11: 12 | H11: 0.09
A12: 31.03.2029 | B12: =B11 -> 54939 | C12: =+B12*12 -> 659268 | D12: =ROUND(+F11*H12,0) -> 316443 | E12: =E11+D12 -> 1092720 | F12: =ROUND(+F11-C12,0) -> 2856769 | G12: 12 | H12: 0.09
A13: 31.03.2030 | B13: =B12 -> 54939 | C13: =+B13*12 -> 659268 | D13: =ROUND(+F12*H13,0) -> 257109 | E13: =E12+D13 -> 1349829 | F13: =ROUND(+F12-C13,0) -> 2197501 | G13: 12 | H13: 0.09
A14: 31.03.2031 | B14: =B13 -> 54939 | C14: =+B14*12 -> 659268 | D14: =ROUND(+F13*H14,0) -> 197775 | E14: =E13+D14 -> 1547604 | F14: =ROUND(+F13-C14,0) -> 1538233 | G14: 12 | H14: 0.09
A15: 31.03.2032 | B15: =B14 -> 54939 | C15: =+B15*12 -> 659268 | D15: =ROUND(+F14*H15,0) -> 138441 | E15: =E14+D15 -> 1686045 | F15: =ROUND(+F14-C15,0) -> 878965 | G15: 12 | H15: 0.09
A16: 31.03.2033 | B16: =B15 -> 54939 | C16: =+B16*12 -> 659268 | D16: =ROUND(+F15*H16,0) -> 79107 | E16: =E15+D16 -> 1765152 | F16: =ROUND(+F15-C16,) -> 219697 | G16: 12 | H16: 0.09
A17: 31.05.2033 | B17: =B16 -> 54939 | C17: =+B17*4 -> 219756 | D17: =ROUND(+F16*H17,0) -> 19773 | E17: =E16+D17 -> 1784925 | F17: =ROUND(+F16-C17,)+59 -> 0 | G17: 4 | H17: 0.09
A18: * For FY 2025-26, EMI is taken as paid for Nov 2026 (Moratorium period 3 Month Aug 26 TO Sep 26)
A20: Loan Amount | B20: 4450000 | E20: Loan Amount | F20: 0
A21: Tenure | B21: 81 month | E21: CC | F21: renual
A22: ROI | B22: 0.09 | E22: ROI | F22: 0
A23: EMI | B23: Rs.54939 | E23: Int Amt | F23: =F20*F22 -> 0
A27: FOR R R ENTERPRISE
F31: Page 14

Sheet all ratio
A2: R R ENTERPRISE
A3: BLOCK NO 203, GOTHAN BRIDGE THI AAGAL UMRA CHOKDI NI BAJUMA,
A4: VELANJA ROAD SURAT, GUJARAT, 395004
A6: PROFITABILITY RATIOS
A7: Profitability Ratios | D7: 2026 | E7: 2027 | F7: 2028 | G7: 2029 | H7: 2030
A8: Gross Profit Ratio | D8: =Ratio!D34 -> 0.15382757 | E8: =Ratio!E34 -> 0.15343926 | F8: =Ratio!F34 -> 0.1415605 | G8: =Ratio!G34 -> 0.14115288 | H8: =Ratio!H34 -> 0.12755558
A9: Net Profit Ratio | D9: =Ratio!D39 -> 0.027881251 | E9: =Ratio!E39 -> 0.036558675 | F9: =Ratio!F39 -> 0.033199408 | G9: =Ratio!G39 -> 0.038631851 | H9: =Ratio!H39 -> 0.035309632
A10: Operating Profit Margin Ratio | D10: 0.0471 | E10: 0.044 | F10: 0.0408 | G10: 0.0407 | H10: 0.0406 | L10: =('trading '!D30-pnl!D28)/'trading '!D13*100 -> 2.7881251 | M10: =('trading '!E30-pnl!E28)/'trading '!E13*100 -> 3.6558675 | N10: =('trading '!F30-pnl!F28)/'trading '!F13*100 -> 3.3199408 | O10: =('trading '!G30-pnl!G28)/'trading '!G13*100 -> 3.8631851 | P10: =('trading '!H30-pnl!H28)/'trading '!H13*100 -> 3.7541115
A11: Operating Ratio | D11: 0.9528 | E11: 0.956 | F11: 0.9591 | G11: 0.9592 | H11: 0.9593 | L11: =('trading '!D28+pnl!D28)/'trading '!D13*100 -> 97.211875 | M11: =('trading '!E28+pnl!E28)/'trading '!E13*100 -> 96.344132 | N11: =('trading '!F28+pnl!F28)/'trading '!F13*100 -> 96.680059 | O11: =('trading '!G28+pnl!G28)/'trading '!G13*100 -> 96.136815 | P11: =('trading '!H28+pnl!H28)/'trading '!H13*100 -> 96.245889
A12: Expense Ratio
A13: Raw Materials to Net Sales | D13: 0.9553 | E13: 0.9098 | F13: 0.9164 | G13: 0.9196 | H13: 0.9224 | L13: ='trading '!D18/'trading '!D13*100 -> 83.801828 | M13: ='trading '!E18/'trading '!E13*100 -> 83.801828 | N13: ='trading '!F18/'trading '!F13*100 -> 84.987934 | O13: ='trading '!G18/'trading '!G13*100 -> 84.987932 | P13: ='trading '!H18/'trading '!H13*100 -> 86.380117
A14: Electricity Expenses to Net Sales | D14: 0.00016 | E14: 0.00014 | F14: 0.0001 | G14: 0.01 | H14: 0.0001 | L14: ='trading '!D21/'trading '!D13*100 -> 0.17934392 | M14: ='trading '!E21/'trading '!E13*100 -> 0.1878852 | N14: ='trading '!F21/'trading '!F13*100 -> 0.18827487 | O14: ='trading '!G21/'trading '!G13*100 -> 0.19724193 | P14: ='trading '!H21/'trading '!H13*100 -> 0.19010504
A15: Direct Labour to Net Sales | D15: 0.0112 | E15: 0.0112 | F15: 0.0112 | G15: 0.0112 | H15: 0.0112 | L15: ='trading '!D23/'trading '!D13*100 -> 1.4391534 | M15: ='trading '!E23/'trading '!E13*100 -> 1.5076846 | N15: ='trading '!F23/'trading '!F13*100 -> 1.5108061 | O15: ='trading '!G23/'trading '!G13*100 -> 1.5827492 | P15: ='trading '!H23/'trading '!H13*100 -> 1.5254677
A16: Transport Exp. To Net Sales | D16: 0.0049 | E16: 0.0047 | F16: 0.0045 | G16: 0.0042 | H16: 0.0038 | L16: =pnl!D19/'trading '!D13*100 -> 0.59779894 | M16: =pnl!E19/'trading '!E13*100 -> 0.62626446 | N16: =pnl!F19/'trading '!F13*100 -> 0.62756176 | O16: =pnl!G19/'trading '!G13*100 -> 0.65744659 | P16: =pnl!H19/'trading '!H13*100 -> 0.63365469
A17: Selling , Gen.& Adm.Exp.to Net Sales
A19: OVERALL PROFITABILITY RATIOS
A20: OVERALL PROFITABILITY RATIOS | D20: 2026 | E20: 2027 | F20: 2028 | G20: 2029 | H20: 2030
A21: Return on Investment (ROI/ROCE) | D21: 0.05 | E21: 0.05 | F21: 0.045 | G21: 0.05 | H21: 0.05 | L21: =pnl!D30/(pnl!D28+'trading '!D28)*100 -> 2.868091 | M21: =pnl!E30/(pnl!E28+'trading '!E28)*100 -> 3.7945928 | N21: =pnl!F30/(pnl!F28+'trading '!F28)*100 -> 3.4339458 | O21: =pnl!G30/(pnl!G28+'trading '!G28)*100 -> 4.0184243 | P21: =pnl!H30/(pnl!H28+'trading '!H28)*100 -> 3.9005422
A24: TURNOVER RATIOS
A25: TURNOVER RATIOS | D25: 2026 | E25: 2027 | F25: 2028 | G25: 2029 | H25: 2030
A26: Capital Turnover Ratio
A27: Fixed Assets Turnover Ratio | D27: 0.8742 | E27: 1.234 | F27: 1.742 | G27: 2.459 | H27: 3.472 | L27: =Ratio!D26/Ratio!D13 -> 4.3483462 | M27: =Ratio!E26/Ratio!E13 -> 5.3714871 | N27: =Ratio!F26/Ratio!F13 -> 6.9369734 | O27: =Ratio!G26/Ratio!G13 -> 8.5692041 | P27: =Ratio!H26/Ratio!H13 -> 11.505963
A28: Net Working Capital Ratio | D28: 0.1488 | E28: 0.2589 | F28: 0.355 | G28: 0.4903 | H28: 0.6818 | L28: =(Ratio!D70-Ratio!D75)/Ratio!D13 -> 0.46425764 | M28: =(Ratio!E70-Ratio!E75)/Ratio!E13 -> 1.1731333 | N28: =(Ratio!F70-Ratio!F75)/Ratio!F13 -> 1.663327 | O28: =(Ratio!G70-Ratio!G75)/Ratio!G13 -> 2.3598195 | P28: =(Ratio!H70-Ratio!H75)/Ratio!H13 -> 3.2244561
A29: Stock Turnover Ratio | D29: 0.0883 | E29: 0.081 | F29: 0.0933 | G29: 0.107 | H29: 0.1228 | L29: ='trading '!D28/'all ratio'!R29 -> 8.614169 | M29: ='trading '!E28/'all ratio'!S29 -> 8.2263892 | N29: ='trading '!F28/'all ratio'!T29 -> 8.324585 | O29: ='trading '!G28/'all ratio'!U29 -> 7.949968 | P29: ='trading '!H28/'all ratio'!V29 -> 8.3790744 | R29: =('trading '!D16+'trading '!D26)/2 -> 2552760 | S29: =('trading '!E16+'trading '!E26)/2 -> 2808036 | T29: =('trading '!F16+'trading '!F26)/2 -> 3088839.5 | U29: =('trading '!G16+'trading '!G26)/2 -> 3397723.5 | V29: =('trading '!H16+'trading '!H26)/2 -> 3737496
A30: Debtors Turnover Ratio | D30: 0.2233 | E30: 0.2144 | F30: 0.2058 | G30: 0.1976 | H30: 0.1897 | L30: ='trading '!D13/bs!D34 -> 16.496753 | M30: ='trading '!E13/bs!E34 -> 15.746901 | N30: ='trading '!F13/bs!F34 -> 15.714366 | O30: ='trading '!G13/bs!G34 -> 15.000073 | P30: ='trading '!H13/bs!H34 -> 15.563316
A31: Creditors Turnover Ratio | D31: 0.4928 | E31: 0.5632 | F31: 0.6436 | G31: 0.7356 | H31: 0.8407 | L31: ='trading '!D13/bs!D21 -> 18.001372 | M31: ='trading '!E13/bs!E21 -> 17.183127 | N31: ='trading '!F13/bs!F21 -> 14.50953 | O31: ='trading '!G13/bs!G21 -> 12.695839 | P31: ='trading '!H13/bs!H21 -> 12.074847
A33: LIQUIDITY RATIO
A34: LIQUIDITY RATIO | D34: 2026 | E34: 2027 | F34: 2028 | G34: 2029 | H34: 2030
A35: Current Ratio | D35: =Ratio!D78 -> 0.015594304 | E35: =Ratio!E78 -> 0.023407785 | F35: =Ratio!F78 -> 0.026852021 | G35: =Ratio!G78 -> 0.031569207 | H35: =Ratio!H78 -> 0.036116751
A36: Quick Ratio (Acid Test Ratio) | D36: 0.0117 | E36: 0.0152 | F36: 0.0167 | G36: 0.018 | H36: 0.0211 | L36: =(Ratio!D70-Ratio!D68)/Ratio!D75 -> 1.0202178 | M36: =(Ratio!E70-Ratio!E68)/Ratio!E75 -> 1.6789332 | N36: =(Ratio!F70-Ratio!F68)/Ratio!F75 -> 1.9259345 | O36: =(Ratio!G70-Ratio!G68)/Ratio!G75 -> 2.2704799 | P36: =(Ratio!H70-Ratio!H68)/Ratio!H75 -> 2.5951204
A38: SOLVENCY RATIO
A39: SOLVENCY RATIO | D39: 2026 | E39: 2027 | F39: 2028 | G39: 2029 | H39: 2030
A40: Debt-Equity Ratio | D40: 0.0633 | E40: 0.038 | F40: 0.028 | G40: 0.0216 | H40: 0.0167 | L40: =bs!D18/bs!D11 -> 0 | M40: =bs!E18/bs!E11 -> 0 | N40: =bs!F18/bs!F11 -> 0 | O40: =bs!G18/bs!G11 -> 0 | P40: =bs!H18/bs!H11 -> 0
A41: Interest Coverage Ratio | D41: 0.0092 | E41: 0.0116 | F41: 0.0143 | G41: 0.0192 | H41: 0.025 | L41: =(pnl!D30-pnl!D20-pnl!D25)/pnl!D20 -> -1.4574442 | M41: =(pnl!E30-pnl!E20-pnl!E25)/pnl!E20 -> -0.25553733 | N41: =(pnl!F30-pnl!F20-pnl!F25)/pnl!F20 -> 0.34863813 | O41: =(pnl!G30-pnl!G20-pnl!G25)/pnl!G20 -> 2.3597775 | P41: =(pnl!H30-pnl!H20-pnl!H25)/pnl!H20 -> 5.3535802
A42: Debt to Total Funds Ratio | D42: 0.008 | E42: 0.0075 | F42: 0.007 | G42: 0.0064 | H42: 0.0059 | L42: =Ratio!D21/Ratio!D16 -> 0.43750168 | M42: =Ratio!E21/Ratio!E16 -> 0.39793541 | N42: =Ratio!F21/Ratio!F16 -> 0.37714701 | O42: =Ratio!G21/Ratio!G16 -> 0.34770188 | P42: =Ratio!H21/Ratio!H16 -> 0.32409863
A43: Fixed Assets Ratio | D43: 0.8742 | E43: 1.2342 | F43: 1.7424 | G43: 2.4599 | H43: 3.4728 | L43: =Ratio!D26/Ratio!D13 -> 4.3483462 | M43: =Ratio!E26/Ratio!E13 -> 5.3714871 | N43: =Ratio!F26/Ratio!F13 -> 6.9369734 | O43: =Ratio!G26/Ratio!G13 -> 8.5692041 | P43: =Ratio!H26/Ratio!H13 -> 11.505963
A44: Partnarship Ratio | D44: 0.0011 | E44: 0.0018 | F44: 0.0023 | G44: 0.0027 | H44: 0.0032 | L44: =bs!D11/bs!D38 -> 0.5003706 | M44: =bs!E11/bs!E38 -> 0.52656013 | N44: =bs!F11/bs!F38 -> 0.55974767 | O44: =bs!G11/bs!G38 -> 0.58107543 | P44: =bs!H11/bs!H38 -> 0.61163551
A47: FOR R R ENTERPRISE
G48: page 12
